[2024-04-27T18:56:19.365+0000] {local_task_job_runner.py:120} INFO - ::group::Pre task execution logs
[2024-04-27T18:56:19.389+0000] {taskinstance.py:2073} INFO - Dependencies all met for dep_context=non-requeueable deps ti=<TaskInstance: csv_transform.transform_csv manual__2024-04-27T18:51:12.851399+00:00 [queued]>
[2024-04-27T18:56:19.396+0000] {taskinstance.py:2073} INFO - Dependencies all met for dep_context=requeueable deps ti=<TaskInstance: csv_transform.transform_csv manual__2024-04-27T18:51:12.851399+00:00 [queued]>
[2024-04-27T18:56:19.397+0000] {taskinstance.py:2303} INFO - Starting attempt 2 of 2
[2024-04-27T18:56:19.412+0000] {taskinstance.py:2327} INFO - Executing <Task(PythonOperator): transform_csv> on 2024-04-27 18:51:12.851399+00:00
[2024-04-27T18:56:19.425+0000] {warnings.py:110} WARNING - /home/***/.local/lib/python3.12/site-packages/***/task/task_runner/standard_task_runner.py:61: DeprecationWarning: This process (pid=1103) is multi-threaded, use of fork() may lead to deadlocks in the child.
  pid = os.fork()

[2024-04-27T18:56:19.427+0000] {standard_task_runner.py:63} INFO - Started process 1105 to run task
[2024-04-27T18:56:19.425+0000] {standard_task_runner.py:90} INFO - Running: ['***', 'tasks', 'run', 'csv_transform', 'transform_csv', 'manual__2024-04-27T18:51:12.851399+00:00', '--job-id', '71', '--raw', '--subdir', 'DAGS_FOLDER/csv_dags.py', '--cfg-path', '/tmp/tmpmwtvrc4m']
[2024-04-27T18:56:19.428+0000] {standard_task_runner.py:91} INFO - Job 71: Subtask transform_csv
[2024-04-27T18:56:19.473+0000] {task_command.py:426} INFO - Running <TaskInstance: csv_transform.transform_csv manual__2024-04-27T18:51:12.851399+00:00 [running]> on host ff7143738b80
[2024-04-27T18:56:19.570+0000] {taskinstance.py:2644} INFO - Exporting env vars: AIRFLOW_CTX_DAG_OWNER='***' AIRFLOW_CTX_DAG_ID='csv_transform' AIRFLOW_CTX_TASK_ID='transform_csv' AIRFLOW_CTX_EXECUTION_DATE='2024-04-27T18:51:12.851399+00:00' AIRFLOW_CTX_TRY_NUMBER='2' AIRFLOW_CTX_DAG_RUN_ID='manual__2024-04-27T18:51:12.851399+00:00'
[2024-04-27T18:56:19.575+0000] {taskinstance.py:430} INFO - ::endgroup::
[2024-04-27T18:56:19.604+0000] {taskinstance.py:441} INFO - ::group::Post task execution logs
[2024-04-27T18:56:19.605+0000] {taskinstance.py:2890} ERROR - Task failed with exception
Traceback (most recent call last):
  File "/home/airflow/.local/lib/python3.12/site-packages/airflow/models/taskinstance.py", line 465, in _execute_task
    result = _execute_callable(context=context, **execute_callable_kwargs)
             ^^^^^^^^^^^^^^^^^^^^^^^^^^^^^^^^^^^^^^^^^^^^^^^^^^^^^^^^^^^^^
  File "/home/airflow/.local/lib/python3.12/site-packages/airflow/models/taskinstance.py", line 432, in _execute_callable
    return execute_callable(context=context, **execute_callable_kwargs)
           ^^^^^^^^^^^^^^^^^^^^^^^^^^^^^^^^^^^^^^^^^^^^^^^^^^^^^^^^^^^^
  File "/home/airflow/.local/lib/python3.12/site-packages/airflow/models/baseoperator.py", line 400, in wrapper
    return func(self, *args, **kwargs)
           ^^^^^^^^^^^^^^^^^^^^^^^^^^^
  File "/home/airflow/.local/lib/python3.12/site-packages/airflow/operators/python.py", line 235, in execute
    return_value = self.execute_callable()
                   ^^^^^^^^^^^^^^^^^^^^^^^
  File "/home/airflow/.local/lib/python3.12/site-packages/airflow/operators/python.py", line 252, in execute_callable
    return self.python_callable(*self.op_args, **self.op_kwargs)
           ^^^^^^^^^^^^^^^^^^^^^^^^^^^^^^^^^^^^^^^^^^^^^^^^^^^^^
  File "/opt/airflow/dags/csv_dags.py", line 20, in transform_csv
    df = pd.read_csv(input_file)
         ^^^^^^^^^^^^^^^^^^^^^^^
  File "/home/airflow/.local/lib/python3.12/site-packages/pandas/io/parsers/readers.py", line 948, in read_csv
    return _read(filepath_or_buffer, kwds)
           ^^^^^^^^^^^^^^^^^^^^^^^^^^^^^^^
  File "/home/airflow/.local/lib/python3.12/site-packages/pandas/io/parsers/readers.py", line 611, in _read
    parser = TextFileReader(filepath_or_buffer, **kwds)
             ^^^^^^^^^^^^^^^^^^^^^^^^^^^^^^^^^^^^^^^^^^
  File "/home/airflow/.local/lib/python3.12/site-packages/pandas/io/parsers/readers.py", line 1448, in __init__
    self._engine = self._make_engine(f, self.engine)
                   ^^^^^^^^^^^^^^^^^^^^^^^^^^^^^^^^^
  File "/home/airflow/.local/lib/python3.12/site-packages/pandas/io/parsers/readers.py", line 1705, in _make_engine
    self.handles = get_handle(
                   ^^^^^^^^^^^
  File "/home/airflow/.local/lib/python3.12/site-packages/pandas/io/common.py", line 863, in get_handle
    handle = open(
             ^^^^^
IsADirectoryError: [Errno 21] Is a directory: 'data_input'
[2024-04-27T18:56:19.623+0000] {taskinstance.py:1205} INFO - Marking task as FAILED. dag_id=csv_transform, task_id=transform_csv, execution_date=20240427T185112, start_date=20240427T185619, end_date=20240427T185619
[2024-04-27T18:56:19.638+0000] {standard_task_runner.py:110} ERROR - Failed to execute job 71 for task transform_csv ([Errno 21] Is a directory: 'data_input'; 1105)
[2024-04-27T18:56:19.682+0000] {local_task_job_runner.py:240} INFO - Task exited with return code 1
[2024-04-27T18:56:19.707+0000] {taskinstance.py:3482} INFO - 0 downstream tasks scheduled from follow-on schedule check
[2024-04-27T18:56:19.710+0000] {local_task_job_runner.py:222} INFO - ::endgroup::
