[2024-04-27T17:49:19.397+0000] {local_task_job_runner.py:120} INFO - ::group::Pre task execution logs
[2024-04-27T17:49:19.437+0000] {taskinstance.py:2073} INFO - Dependencies all met for dep_context=non-requeueable deps ti=<TaskInstance: csv_transform_copy.transform_csv manual__2024-04-27T17:49:15.104616+00:00 [queued]>
[2024-04-27T17:49:19.447+0000] {taskinstance.py:2073} INFO - Dependencies all met for dep_context=requeueable deps ti=<TaskInstance: csv_transform_copy.transform_csv manual__2024-04-27T17:49:15.104616+00:00 [queued]>
[2024-04-27T17:49:19.448+0000] {taskinstance.py:2303} INFO - Starting attempt 1 of 2
[2024-04-27T17:49:19.464+0000] {taskinstance.py:2327} INFO - Executing <Task(PythonOperator): transform_csv> on 2024-04-27 17:49:15.104616+00:00
[2024-04-27T17:49:19.475+0000] {warnings.py:110} WARNING - /home/***/.local/lib/python3.12/site-packages/***/task/task_runner/standard_task_runner.py:61: DeprecationWarning: This process (pid=352) is multi-threaded, use of fork() may lead to deadlocks in the child.
  pid = os.fork()

[2024-04-27T17:49:19.477+0000] {standard_task_runner.py:63} INFO - Started process 353 to run task
[2024-04-27T17:49:19.477+0000] {standard_task_runner.py:90} INFO - Running: ['***', 'tasks', 'run', 'csv_transform_copy', 'transform_csv', 'manual__2024-04-27T17:49:15.104616+00:00', '--job-id', '36', '--raw', '--subdir', 'DAGS_FOLDER/csv_dag.py', '--cfg-path', '/tmp/tmpddat98bj']
[2024-04-27T17:49:19.479+0000] {standard_task_runner.py:91} INFO - Job 36: Subtask transform_csv
[2024-04-27T17:49:19.534+0000] {task_command.py:426} INFO - Running <TaskInstance: csv_transform_copy.transform_csv manual__2024-04-27T17:49:15.104616+00:00 [running]> on host ff7143738b80
[2024-04-27T17:49:19.632+0000] {taskinstance.py:2644} INFO - Exporting env vars: AIRFLOW_CTX_DAG_OWNER='***' AIRFLOW_CTX_DAG_ID='csv_transform_copy' AIRFLOW_CTX_TASK_ID='transform_csv' AIRFLOW_CTX_EXECUTION_DATE='2024-04-27T17:49:15.104616+00:00' AIRFLOW_CTX_TRY_NUMBER='1' AIRFLOW_CTX_DAG_RUN_ID='manual__2024-04-27T17:49:15.104616+00:00'
[2024-04-27T17:49:19.635+0000] {taskinstance.py:430} INFO - ::endgroup::
[2024-04-27T17:49:21.532+0000] {taskinstance.py:441} INFO - ::group::Post task execution logs
[2024-04-27T17:49:21.539+0000] {taskinstance.py:2890} ERROR - Task failed with exception
Traceback (most recent call last):
  File "/home/airflow/.local/lib/python3.12/site-packages/airflow/models/taskinstance.py", line 465, in _execute_task
    result = _execute_callable(context=context, **execute_callable_kwargs)
             ^^^^^^^^^^^^^^^^^^^^^^^^^^^^^^^^^^^^^^^^^^^^^^^^^^^^^^^^^^^^^
  File "/home/airflow/.local/lib/python3.12/site-packages/airflow/models/taskinstance.py", line 432, in _execute_callable
    return execute_callable(context=context, **execute_callable_kwargs)
           ^^^^^^^^^^^^^^^^^^^^^^^^^^^^^^^^^^^^^^^^^^^^^^^^^^^^^^^^^^^^
  File "/home/airflow/.local/lib/python3.12/site-packages/airflow/models/baseoperator.py", line 400, in wrapper
    return func(self, *args, **kwargs)
           ^^^^^^^^^^^^^^^^^^^^^^^^^^^
  File "/home/airflow/.local/lib/python3.12/site-packages/airflow/operators/python.py", line 235, in execute
    return_value = self.execute_callable()
                   ^^^^^^^^^^^^^^^^^^^^^^^
  File "/home/airflow/.local/lib/python3.12/site-packages/airflow/operators/python.py", line 252, in execute_callable
    return self.python_callable(*self.op_args, **self.op_kwargs)
           ^^^^^^^^^^^^^^^^^^^^^^^^^^^^^^^^^^^^^^^^^^^^^^^^^^^^^
  File "/opt/airflow/dags/csv_dag.py", line 18, in transform_csv
    df = pd.read_csv(input_path)
         ^^^^^^^^^^^^^^^^^^^^^^^
  File "/home/airflow/.local/lib/python3.12/site-packages/pandas/io/parsers/readers.py", line 948, in read_csv
    return _read(filepath_or_buffer, kwds)
           ^^^^^^^^^^^^^^^^^^^^^^^^^^^^^^^
  File "/home/airflow/.local/lib/python3.12/site-packages/pandas/io/parsers/readers.py", line 611, in _read
    parser = TextFileReader(filepath_or_buffer, **kwds)
             ^^^^^^^^^^^^^^^^^^^^^^^^^^^^^^^^^^^^^^^^^^
  File "/home/airflow/.local/lib/python3.12/site-packages/pandas/io/parsers/readers.py", line 1448, in __init__
    self._engine = self._make_engine(f, self.engine)
                   ^^^^^^^^^^^^^^^^^^^^^^^^^^^^^^^^^
  File "/home/airflow/.local/lib/python3.12/site-packages/pandas/io/parsers/readers.py", line 1705, in _make_engine
    self.handles = get_handle(
                   ^^^^^^^^^^^
  File "/home/airflow/.local/lib/python3.12/site-packages/pandas/io/common.py", line 863, in get_handle
    handle = open(
             ^^^^^
FileNotFoundError: [Errno 2] No such file or directory: './data_input/data.csv'
[2024-04-27T17:49:21.641+0000] {taskinstance.py:1205} INFO - Marking task as UP_FOR_RETRY. dag_id=csv_transform_copy, task_id=transform_csv, execution_date=20240427T174915, start_date=20240427T174919, end_date=20240427T174921
[2024-04-27T17:49:21.666+0000] {standard_task_runner.py:110} ERROR - Failed to execute job 36 for task transform_csv ([Errno 2] No such file or directory: './data_input/data.csv'; 353)
[2024-04-27T17:49:21.703+0000] {local_task_job_runner.py:240} INFO - Task exited with return code 1
[2024-04-27T17:49:21.724+0000] {taskinstance.py:3482} INFO - 0 downstream tasks scheduled from follow-on schedule check
[2024-04-27T17:49:21.727+0000] {local_task_job_runner.py:222} INFO - ::endgroup::
