[2024-04-28T17:35:07.623+0000] {local_task_job_runner.py:120} INFO - ::group::Pre task execution logs
[2024-04-28T17:35:07.665+0000] {taskinstance.py:2073} INFO - Dependencies all met for dep_context=non-requeueable deps ti=<TaskInstance: csv_processing_dag.process_csv_files manual__2024-04-28T17:35:03.241671+00:00 [queued]>
[2024-04-28T17:35:07.680+0000] {taskinstance.py:2073} INFO - Dependencies all met for dep_context=requeueable deps ti=<TaskInstance: csv_processing_dag.process_csv_files manual__2024-04-28T17:35:03.241671+00:00 [queued]>
[2024-04-28T17:35:07.681+0000] {taskinstance.py:2303} INFO - Starting attempt 1 of 2
[2024-04-28T17:35:07.706+0000] {taskinstance.py:2327} INFO - Executing <Task(PythonOperator): process_csv_files> on 2024-04-28 17:35:03.241671+00:00
[2024-04-28T17:35:07.736+0000] {warnings.py:110} WARNING - /home/***/.local/lib/python3.12/site-packages/***/task/task_runner/standard_task_runner.py:61: DeprecationWarning: This process (pid=154) is multi-threaded, use of fork() may lead to deadlocks in the child.
  pid = os.fork()

[2024-04-28T17:35:07.739+0000] {standard_task_runner.py:63} INFO - Started process 156 to run task
[2024-04-28T17:35:07.737+0000] {standard_task_runner.py:90} INFO - Running: ['***', 'tasks', 'run', 'csv_processing_dag', 'process_csv_files', 'manual__2024-04-28T17:35:03.241671+00:00', '--job-id', '98', '--raw', '--subdir', 'DAGS_FOLDER/csv_dags.py', '--cfg-path', '/tmp/tmpbcg1ges1']
[2024-04-28T17:35:07.742+0000] {standard_task_runner.py:91} INFO - Job 98: Subtask process_csv_files
[2024-04-28T17:35:07.812+0000] {task_command.py:426} INFO - Running <TaskInstance: csv_processing_dag.process_csv_files manual__2024-04-28T17:35:03.241671+00:00 [running]> on host 4cdb6c1dd19f
[2024-04-28T17:35:07.958+0000] {taskinstance.py:2644} INFO - Exporting env vars: AIRFLOW_CTX_DAG_OWNER='***' AIRFLOW_CTX_DAG_ID='csv_processing_dag' AIRFLOW_CTX_TASK_ID='process_csv_files' AIRFLOW_CTX_EXECUTION_DATE='2024-04-28T17:35:03.241671+00:00' AIRFLOW_CTX_TRY_NUMBER='1' AIRFLOW_CTX_DAG_RUN_ID='manual__2024-04-28T17:35:03.241671+00:00'
[2024-04-28T17:35:07.960+0000] {taskinstance.py:430} INFO - ::endgroup::
[2024-04-28T17:35:07.994+0000] {taskinstance.py:441} INFO - ::group::Post task execution logs
[2024-04-28T17:35:07.995+0000] {taskinstance.py:2890} ERROR - Task failed with exception
Traceback (most recent call last):
  File "/home/airflow/.local/lib/python3.12/site-packages/airflow/models/taskinstance.py", line 465, in _execute_task
    result = _execute_callable(context=context, **execute_callable_kwargs)
             ^^^^^^^^^^^^^^^^^^^^^^^^^^^^^^^^^^^^^^^^^^^^^^^^^^^^^^^^^^^^^
  File "/home/airflow/.local/lib/python3.12/site-packages/airflow/models/taskinstance.py", line 432, in _execute_callable
    return execute_callable(context=context, **execute_callable_kwargs)
           ^^^^^^^^^^^^^^^^^^^^^^^^^^^^^^^^^^^^^^^^^^^^^^^^^^^^^^^^^^^^
  File "/home/airflow/.local/lib/python3.12/site-packages/airflow/models/baseoperator.py", line 400, in wrapper
    return func(self, *args, **kwargs)
           ^^^^^^^^^^^^^^^^^^^^^^^^^^^
  File "/home/airflow/.local/lib/python3.12/site-packages/airflow/operators/python.py", line 235, in execute
    return_value = self.execute_callable()
                   ^^^^^^^^^^^^^^^^^^^^^^^
  File "/home/airflow/.local/lib/python3.12/site-packages/airflow/operators/python.py", line 252, in execute_callable
    return self.python_callable(*self.op_args, **self.op_kwargs)
           ^^^^^^^^^^^^^^^^^^^^^^^^^^^^^^^^^^^^^^^^^^^^^^^^^^^^^
  File "/opt/airflow/dags/csv_dags.py", line 36, in process_csv_files
    for filename in os.listdir(directory):
                    ^^^^^^^^^^^^^^^^^^^^^
FileNotFoundError: [Errno 2] No such file or directory: '../data_input'
[2024-04-28T17:35:08.014+0000] {taskinstance.py:1205} INFO - Marking task as UP_FOR_RETRY. dag_id=csv_processing_dag, task_id=process_csv_files, execution_date=20240428T173503, start_date=20240428T173507, end_date=20240428T173508
[2024-04-28T17:35:08.058+0000] {standard_task_runner.py:110} ERROR - Failed to execute job 98 for task process_csv_files ([Errno 2] No such file or directory: '../data_input'; 156)
[2024-04-28T17:35:08.077+0000] {local_task_job_runner.py:240} INFO - Task exited with return code 1
[2024-04-28T17:35:08.113+0000] {taskinstance.py:3482} INFO - 0 downstream tasks scheduled from follow-on schedule check
[2024-04-28T17:35:08.117+0000] {local_task_job_runner.py:222} INFO - ::endgroup::
