[2024-04-27T18:06:10.247+0000] {task_context_logger.py:104} ERROR - Executor reports task instance <TaskInstance: csv_transform_copy.process_csv manual__2024-04-27T18:05:39.930618+00:00 [queued]> finished (failed) although the task says it's queued. (Info: None) Was the task killed externally?
