[2024-04-27T18:58:36.809+0000] {task_context_logger.py:104} ERROR - Executor reports task instance <TaskInstance: csv_transform.transform_csv manual__2024-04-27T18:58:32.783389+00:00 [queued]> finished (failed) although the task says it's queued. (Info: None) Was the task killed externally?
