[2024-04-27T19:13:54.714+0000] {task_context_logger.py:104} ERROR - Executor reports task instance <TaskInstance: csv_transform.process_csv manual__2024-04-27T19:13:06.197144+00:00 [queued]> finished (failed) although the task says it's queued. (Info: None) Was the task killed externally?
