[2024-04-27T17:55:20.559+0000] {local_task_job_runner.py:120} INFO - ::group::Pre task execution logs
[2024-04-27T17:55:20.591+0000] {taskinstance.py:2073} INFO - Dependencies all met for dep_context=non-requeueable deps ti=<TaskInstance: csv_transform_copy.transform_csv manual__2024-04-27T17:49:43.618209+00:00 [queued]>
[2024-04-27T17:55:20.599+0000] {taskinstance.py:2073} INFO - Dependencies all met for dep_context=requeueable deps ti=<TaskInstance: csv_transform_copy.transform_csv manual__2024-04-27T17:49:43.618209+00:00 [queued]>
[2024-04-27T17:55:20.600+0000] {taskinstance.py:2303} INFO - Starting attempt 2 of 2
[2024-04-27T17:55:20.615+0000] {taskinstance.py:2327} INFO - Executing <Task(PythonOperator): transform_csv> on 2024-04-27 17:49:43.618209+00:00
[2024-04-27T17:55:20.623+0000] {warnings.py:110} WARNING - /home/***/.local/lib/python3.12/site-packages/***/task/task_runner/standard_task_runner.py:61: DeprecationWarning: This process (pid=431) is multi-threaded, use of fork() may lead to deadlocks in the child.
  pid = os.fork()

[2024-04-27T17:55:20.626+0000] {standard_task_runner.py:63} INFO - Started process 432 to run task
[2024-04-27T17:55:20.625+0000] {standard_task_runner.py:90} INFO - Running: ['***', 'tasks', 'run', 'csv_transform_copy', 'transform_csv', 'manual__2024-04-27T17:49:43.618209+00:00', '--job-id', '43', '--raw', '--subdir', 'DAGS_FOLDER/csv_dag.py', '--cfg-path', '/tmp/tmppcdu422y']
[2024-04-27T17:55:20.628+0000] {standard_task_runner.py:91} INFO - Job 43: Subtask transform_csv
[2024-04-27T17:55:20.680+0000] {task_command.py:426} INFO - Running <TaskInstance: csv_transform_copy.transform_csv manual__2024-04-27T17:49:43.618209+00:00 [running]> on host ff7143738b80
[2024-04-27T17:55:20.760+0000] {taskinstance.py:2644} INFO - Exporting env vars: AIRFLOW_CTX_DAG_OWNER='***' AIRFLOW_CTX_DAG_ID='csv_transform_copy' AIRFLOW_CTX_TASK_ID='transform_csv' AIRFLOW_CTX_EXECUTION_DATE='2024-04-27T17:49:43.618209+00:00' AIRFLOW_CTX_TRY_NUMBER='2' AIRFLOW_CTX_DAG_RUN_ID='manual__2024-04-27T17:49:43.618209+00:00'
[2024-04-27T17:55:20.762+0000] {taskinstance.py:430} INFO - ::endgroup::
[2024-04-27T17:55:22.605+0000] {taskinstance.py:441} INFO - ::group::Post task execution logs
[2024-04-27T17:55:22.617+0000] {taskinstance.py:2890} ERROR - Task failed with exception
Traceback (most recent call last):
  File "/home/airflow/.local/lib/python3.12/site-packages/airflow/models/taskinstance.py", line 465, in _execute_task
    result = _execute_callable(context=context, **execute_callable_kwargs)
             ^^^^^^^^^^^^^^^^^^^^^^^^^^^^^^^^^^^^^^^^^^^^^^^^^^^^^^^^^^^^^
  File "/home/airflow/.local/lib/python3.12/site-packages/airflow/models/taskinstance.py", line 432, in _execute_callable
    return execute_callable(context=context, **execute_callable_kwargs)
           ^^^^^^^^^^^^^^^^^^^^^^^^^^^^^^^^^^^^^^^^^^^^^^^^^^^^^^^^^^^^
  File "/home/airflow/.local/lib/python3.12/site-packages/airflow/models/baseoperator.py", line 400, in wrapper
    return func(self, *args, **kwargs)
           ^^^^^^^^^^^^^^^^^^^^^^^^^^^
  File "/home/airflow/.local/lib/python3.12/site-packages/airflow/operators/python.py", line 235, in execute
    return_value = self.execute_callable()
                   ^^^^^^^^^^^^^^^^^^^^^^^
  File "/home/airflow/.local/lib/python3.12/site-packages/airflow/operators/python.py", line 252, in execute_callable
    return self.python_callable(*self.op_args, **self.op_kwargs)
           ^^^^^^^^^^^^^^^^^^^^^^^^^^^^^^^^^^^^^^^^^^^^^^^^^^^^^
  File "/opt/airflow/dags/csv_dag.py", line 18, in transform_csv
    df = pd.read_csv(input_path)
         ^^^^^^^^^^^^^^^^^^^^^^^
  File "/home/airflow/.local/lib/python3.12/site-packages/pandas/io/parsers/readers.py", line 948, in read_csv
    return _read(filepath_or_buffer, kwds)
           ^^^^^^^^^^^^^^^^^^^^^^^^^^^^^^^
  File "/home/airflow/.local/lib/python3.12/site-packages/pandas/io/parsers/readers.py", line 611, in _read
    parser = TextFileReader(filepath_or_buffer, **kwds)
             ^^^^^^^^^^^^^^^^^^^^^^^^^^^^^^^^^^^^^^^^^^
  File "/home/airflow/.local/lib/python3.12/site-packages/pandas/io/parsers/readers.py", line 1448, in __init__
    self._engine = self._make_engine(f, self.engine)
                   ^^^^^^^^^^^^^^^^^^^^^^^^^^^^^^^^^
  File "/home/airflow/.local/lib/python3.12/site-packages/pandas/io/parsers/readers.py", line 1705, in _make_engine
    self.handles = get_handle(
                   ^^^^^^^^^^^
  File "/home/airflow/.local/lib/python3.12/site-packages/pandas/io/common.py", line 863, in get_handle
    handle = open(
             ^^^^^
FileNotFoundError: [Errno 2] No such file or directory: 'data_input/data.csv'
[2024-04-27T17:55:32.709+0000] {standard_task_runner.py:110} ERROR - Failed to execute job 43 for task transform_csv ((psycopg2.OperationalError) could not translate host name "postgres" to address: Temporary failure in name resolution

(Background on this error at: https://sqlalche.me/e/14/e3q8); 432)
[2024-04-27T17:55:33.212+0000] {local_task_job_runner.py:240} INFO - Task exited with return code 1
[2024-04-27T17:55:33.245+0000] {taskinstance.py:3482} INFO - 0 downstream tasks scheduled from follow-on schedule check
[2024-04-27T17:55:33.272+0000] {local_task_job_runner.py:222} INFO - ::endgroup::
