[2024-04-28T18:29:30.672+0000] {task_context_logger.py:104} ERROR - Executor reports task instance <TaskInstance: csv_processing_dag.process_csv_files manual__2024-04-28T18:25:47.167303+00:00 [queued]> finished (failed) although the task says it's queued. (Info: None) Was the task killed externally?
